<?xml version="1.0" encoding="utf-8"?>
<!-- This URDF was automatically created by SolidWorks to URDF Exporter! Originally created by Stephen Brawner (brawner@gmail.com) 
     Commit Version: 1.5.1-0-g916b5db  Build Version: 1.5.7152.31018
     For more information, please see http://wiki.ros.org/sw_urdf_exporter -->
<robot
  name="Covid_Bot_URDF">
  <link
    name="base_link">
    <inertial>
      <origin
        xyz="0.059253 -3.5103E-05 0.27273"
        rpy="0 0 0" />
      <mass
        value="5.0138" />
      <inertia
        ixx="0.022066"
        ixy="-5.352E-07"
        ixz="-3.5279E-05"
        iyy="0.051738"
        iyz="2.1059E-07"
        izz="0.053855" />
    </inertial>
    <visual>
      <origin
        xyz="0 0 0"
        rpy="0 0 0" />
      <geometry>
        <mesh
          filename="meshes/base_link.STL" />
      </geometry>
      <material
        name="">
        <color
          rgba="1 1 1 1" />
      </material>
    </visual>
    <collision>
      <origin
        xyz="0 0 0"
        rpy="0 0 0" />
      <geometry>
        <mesh
          filename="meshes/base_link.STL" />
      </geometry>
    </collision>
  </link>
  <link
    name="Waist_Link">
    <inertial>
      <origin
        xyz="0.018764 -0.02698 0.23455"
        rpy="0 0 0" />
      <mass
        value="0.85886" />
      <inertia
        ixx="0.0075486"
        ixy="-8.8132E-05"
        ixz="-1.1514E-05"
        iyy="0.0076505"
        iyz="-6.4529E-06"
        izz="0.00051864" />
    </inertial>
    <visual>
      <origin
        xyz="0 0 0"
        rpy="0 0 0" />
      <geometry>
        <mesh
          filename="meshes/Waist_Link.STL" />
      </geometry>
      <material
        name="">
        <color
          rgba="0.79216 0.81961 0.93333 1" />
      </material>
    </visual>
    <collision>
      <origin
        xyz="0 0 0"
        rpy="0 0 0" />
      <geometry>
        <mesh
          filename="meshes/Waist_Link.STL" />
      </geometry>
    </collision>
  </link>
  <joint
    name="Waist_Joint"
    type="revolute">
    <origin
      xyz="0.14905 0 0.59309"
      rpy="0 0 -0.5236" />
    <parent
      link="base_link" />
    <child
      link="Waist_Link" />
    <axis
      xyz="0 0 -1" />
    <limit
      lower="-3.1416"
      upper="3.1416"
      effort="15"
      velocity="65" />
  </joint>
  <link
    name="Shoulder_Link">
    <inertial>
      <origin
        xyz="4.66842554336377E-08 0.265693440313095 -0.0148861722444303"
        rpy="0 0 0" />
      <mass
        value="0.167183733473788" />
      <inertia
        ixx="0.00432114063992436"
        ixy="4.30760476432212E-12"
        ixz="1.58852641360613E-15"
        iyy="2.81708148404114E-05"
        iyz="2.44707368818259E-16"
        izz="0.00434846549615947" />
    </inertial>
    <visual>
      <origin
        xyz="0 0 0"
        rpy="0 0 0" />
      <geometry>
        <mesh
          filename="meshes/Shoulder_Link.STL" />
      </geometry>
      <material
        name="">
        <color
          rgba="0.792156862745098 0.819607843137255 0.933333333333333 1" />
      </material>
    </visual>
    <collision>
      <origin
        xyz="0 0 0"
        rpy="0 0 0" />
      <geometry>
        <mesh
          filename="meshes/Shoulder_Link.STL" />
      </geometry>
    </collision>
  </link>
  <joint
    name="Shoulder_Joint"
    type="revolute">
    <origin
      xyz="0.0087383 -0.015135 0.064525"
      rpy="1.5708 0.00097668 0.5236" />
    <parent
      link="Waist_Link" />
    <child
      link="Shoulder_Link" />
    <axis
      xyz="0 0 1" />
    <limit
      lower="-1.5708"
      upper="1.5708"
      effort="15"
      velocity="65" />
  </joint>
  <link
    name="Elbow_Link">
    <inertial>
      <origin
        xyz="0.351846192147882 0.0339993945889256 -0.00950589374198291"
        rpy="0 0 0" />
      <mass
        value="0.120438255580755" />
      <inertia
        ixx="2.10110877179701E-05"
        ixy="-2.11476741427197E-06"
        ixz="-9.1744583661404E-09"
        iyy="0.00117217890712797"
        iyz="8.89017312883176E-11"
        izz="0.00116979199301081" />
    </inertial>
    <visual>
      <origin
        xyz="0 0 0"
        rpy="0 0 0" />
      <geometry>
        <mesh
          filename="meshes/Elbow_Link.STL" />
      </geometry>
      <material
        name="">
        <color
          rgba="0.792156862745098 0.819607843137255 0.933333333333333 1" />
      </material>
    </visual>
    <collision>
      <origin
        xyz="0 0 0"
        rpy="0 0 0" />
      <geometry>
        <mesh
          filename="meshes/Elbow_Link.STL" />
      </geometry>
    </collision>
  </link>
  <joint
    name="Elbow_Joint"
    type="revolute">
    <origin
      xyz="0 0.55 -0.004675"
      rpy="0 0 1.5008" />
    <parent
      link="Shoulder_Link" />
    <child
      link="Elbow_Link" />
    <axis
      xyz="0 0 -1" />
    <limit
      lower="0"
      upper="3.054326"
      effort="15"
      velocity="65" />
  </joint>
  <link
    name="Wrist_Link">
    <inertial>
      <origin
        xyz="0.00783108623348705 0.115608036588963 0.0267381749860593"
        rpy="0 0 0" />
      <mass
        value="0.299386885230771" />
      <inertia
        ixx="0.00117584897204787"
        ixy="-4.2904322653638E-05"
        ixz="-6.03456037533926E-09"
        iyy="0.000686640201384165"
        iyz="-6.93011784614871E-08"
        izz="0.000517039377850733" />
    </inertial>
    <visual>
      <origin
        xyz="0 0 0"
        rpy="0 0 0" />
      <geometry>
        <mesh
          filename="meshes/Wrist_Link.STL" />
      </geometry>
      <material
        name="">
        <color
          rgba="0.792156862745098 0.819607843137255 0.933333333333333 1" />
      </material>
    </visual>
    <collision>
      <origin
        xyz="0 0 0"
        rpy="0 0 0" />
      <geometry>
        <mesh
          filename="meshes/Wrist_Link.STL" />
      </geometry>
    </collision>
  </link>
  <joint
    name="Wrist_Joint"
    type="revolute">
    <origin
      xyz="0.54315 0.033455 -0.037125"
      rpy="0 0 -1.4998" />
    <parent
      link="Elbow_Link" />
    <child
      link="Wrist_Link" />
    <axis
      xyz="0 0 1" />
    <limit
      lower="-1.5708"
      upper="1.5708"
      effort="1.66"
      velocity="6.5" />
  </joint>
  <link
    name="Wheel_FL_Link">
    <inertial>
      <origin
        xyz="-3.20772142820003E-07 3.20764833999787E-07 -0.000428329520177934"
        rpy="0 0 0" />
      <mass
        value="0.813834380524578" />
      <inertia
        ixx="0.00141713792479969"
        ixy="-4.7255246614082E-09"
        ixz="5.09694171959109E-09"
        iyy="0.00141713792483397"
        iyz="-5.09700208363254E-09"
        izz="0.00261834079951068" />
    </inertial>
    <visual>
      <origin
        xyz="0 0 0"
        rpy="0 0 0" />
      <geometry>
        <mesh
          filename="meshes/Wheel_FL_Link.STL" />
      </geometry>
      <material
        name="">
        <color
          rgba="0.792156862745098 0.819607843137255 0.933333333333333 1" />
      </material>
    </visual>
    <collision>
      <origin
        xyz="0 0 0"
        rpy="0 0 0" />
      <geometry>
        <mesh
          filename="meshes/Wheel_FL_Link.STL" />
      </geometry>
    </collision>
  </link>
  <joint
    name="Wheel_FL_Joint"
    type="continuous">
    <origin
      xyz="0.14923 0.1285 0.093111"
      rpy="1.5708 0.61087 3.1416" />
    <parent
      link="base_link" />
    <child
      link="Wheel_FL_Link" />
    <axis
      xyz="0 0 1" />
    <limit
      effort="15.3"
      velocity="8.3" />
  </joint>
  <link
    name="Wheel_FR_Link">
    <inertial>
      <origin
        xyz="-3.20769391090603E-07 3.20789198648974E-07 -0.000428329520562126"
        rpy="0 0 0" />
      <mass
        value="0.813834380664065" />
      <inertia
        ixx="0.00141713792516499"
        ixy="-4.72572534826032E-09"
        ixz="5.09696347704616E-09"
        iyy="0.00141713792503021"
        iyz="-5.09685770642578E-09"
        izz="0.00261834080005719" />
    </inertial>
    <visual>
      <origin
        xyz="0 0 0"
        rpy="0 0 0" />
      <geometry>
        <mesh
          filename="meshes/Wheel_FR_Link.STL" />
      </geometry>
      <material
        name="">
        <color
          rgba="0.792156862745098 0.819607843137255 0.933333333333333 1" />
      </material>
    </visual>
    <collision>
      <origin
        xyz="0 0 0"
        rpy="0 0 0" />
      <geometry>
        <mesh
          filename="meshes/Wheel_FR_Link.STL" />
      </geometry>
    </collision>
  </link>
  <joint
    name="Wheel_FR_Joint"
    type="continuous">
    <origin
      xyz="0.14923 -0.1285 0.093111"
      rpy="-1.5708 -0.94174 -3.1416" />
    <parent
      link="base_link" />
    <child
      link="Wheel_FR_Link" />
    <axis
      xyz="0 0 1" />
    <limit
      effort="15.3"
      velocity="8.3" />
  </joint>
  <link
    name="Wheel_BL_Link">
    <inertial>
      <origin
        xyz="-3.20778043225167E-07 3.20775929818495E-07 -0.000428329520870602"
        rpy="0 0 0" />
      <mass
        value="0.813834380645934" />
      <inertia
        ixx="0.00141713792485704"
        ixy="-4.7255129068135E-09"
        ixz="5.09690483659598E-09"
        iyy="0.00141713792527423"
        iyz="-5.09690576937866E-09"
        izz="0.0026183407999996" />
    </inertial>
    <visual>
      <origin
        xyz="0 0 0"
        rpy="0 0 0" />
      <geometry>
        <mesh
          filename="meshes/Wheel_BL_Link.STL" />
      </geometry>
      <material
        name="">
        <color
          rgba="0.792156862745098 0.819607843137255 0.933333333333333 1" />
      </material>
    </visual>
    <collision>
      <origin
        xyz="0 0 0"
        rpy="0 0 0" />
      <geometry>
        <mesh
          filename="meshes/Wheel_BL_Link.STL" />
      </geometry>
    </collision>
  </link>
  <joint
    name="Wheel_BL_Joint"
    type="continuous">
    <origin
      xyz="-0.14923 0.1285 0.093122"
      rpy="-1.5708 -0.94166 0" />
    <parent
      link="base_link" />
    <child
      link="Wheel_BL_Link" />
    <axis
      xyz="0 0 1" />
    <limit
      effort="15.3"
      velocity="8.3" />
  </joint>
  <link
    name="Wheel_BR_Link">
    <inertial>
      <origin
        xyz="-3.2076078543275E-07 3.20775953327468E-07 -0.000428329520502591"
        rpy="0 0 0" />
      <mass
        value="0.813834380613537" />
      <inertia
        ixx="0.00141713792459929"
        ixy="-4.72554752403362E-09"
        ixz="5.09700189748719E-09"
        iyy="0.00141713792539451"
        iyz="-5.09691184469431E-09"
        izz="0.00261834079986221" />
    </inertial>
    <visual>
      <origin
        xyz="0 0 0"
        rpy="0 0 0" />
      <geometry>
        <mesh
          filename="meshes/Wheel_BR_Link.STL" />
      </geometry>
      <material
        name="">
        <color
          rgba="0.792156862745098 0.819607843137255 0.933333333333333 1" />
      </material>
    </visual>
    <collision>
      <origin
        xyz="0 0 0"
        rpy="0 0 0" />
      <geometry>
        <mesh
          filename="meshes/Wheel_BR_Link.STL" />
      </geometry>
    </collision>
  </link>
  <joint
    name="Wheel_BR_Joint"
    type="continuous">
    <origin
      xyz="-0.14923 -0.1285 0.093122"
      rpy="1.5708 0.61095 0" />
    <parent
      link="base_link" />
    <child
      link="Wheel_BR_Link" />
    <axis
      xyz="0 0 1" />
    <limit
      effort="15.3"
      velocity="8.3" />
  </joint>
</robot>